<?xml version="1.0"?>

<robot name="lbr_iiwa" xmlns:xacro="http://www.ros.org/wiki/xacro">

  <!-- Import all Gazebo-customization elements, including Gazebo colors -->
  <xacro:include filename="$(find lbr_iiwa_description)/urdf/lbr_iiwa.gazebo.xacro" />
  <!-- Import Rviz colors -->
  <xacro:include filename="$(find lbr_iiwa_description)/urdf/materials.xacro" />
  <!-- Import Utilities -->
  <xacro:include filename="$(find lbr_iiwa_description)/urdf/utilities.xacro"/>

  <!-- some constants -->
  <xacro:property name="safety_controller_k_pos" value="100" />
  <xacro:property name="safety_controller_k_vel" value="2" />
  <xacro:property name="joint_damping" value="0.1" />
  <xacro:property name="velocity_scale_factor" value="1"/>

  <!-- right is either 1 (for right arm) or -1 (for left arm) -->
  <xacro:macro name="lbr_iiwa" params="parent name right *origin">

    <!--joint between {parent} and link_0-->
    <joint name="${parent}_joint" type="fixed">
      <insert_block name="origin"/>
      <parent link="${parent}"/>
      <child link="${name}_link_0"/>
    </joint>

    <link name="${name}_link_0">
      <inertial>
        <origin xyz="0 0 0.07" rpy="0 0 0"/>
        <mass value="5"/>
        <inertia ixx="0.05"  ixy="0"  ixz="0" iyy="0.06" iyz="0" izz="0.03" />
      </inertial>

      <visual>
        <origin xyz="0 0 0" rpy="0 0 0"/>
        <geometry>
          <mesh filename="package://lbr_iiwa_description/meshes/link_0.stl"/>
        </geometry>
        <material name="Grey"/>
      </visual>

      <collision>
        <origin xyz="0 0 0" rpy="0 0 0"/>
        <geometry>
          <mesh filename="package://lbr_iiwa_description/meshes/link_0.stl"/>
        </geometry>
        <material name="Grey"/>
      </collision>
    </link>

    <!-- joint between link_0 and link_1 -->
    <joint name="${name}_joint_1" type="revolute">
      <parent link="${name}_link_0"/>
      <child link="${name}_link_1"/>
      <origin xyz="0 0 0.1575" rpy="0 0 0"/>
      <axis xyz="0 0 1"/>
      <limit lower="${-170 * PI / 180}" upper="${170 * PI / 180}"
             effort="204" velocity="${velocity_scale_factor * 110 * PI / 180}" />
      <!--   <safety_controller soft_lower_limit="${-168 * M_PI / 180}"
           soft_upper_limit="${168 * M_PI / 180}"
           k_position="${safety_controller_k_pos}"
           k_velocity="${safety_controller_k_vel}"/> -->
      <dynamics damping="${joint_damping}"/>
    </joint>

    <link name="${name}_link_1">
      <inertial>
        <origin xyz="0 0.03 0.12" rpy="0 0 0"/>
        <mass value="4"/>
        <inertia ixx="0.1"  ixy="0"  ixz="0" iyy="0.09" iyz="0" izz="0.02" />
      </inertial>

      <visual>
        <origin xyz="0 0 0" rpy="0 0 0"/>
        <geometry>
          <mesh filename="package://lbr_iiwa_description/meshes/link_1.stl"/>
        </geometry>
        <material name="Orange"/>
      </visual>

      <collision>
        <origin xyz="0 0 0" rpy="0 0 0"/>
        <geometry>
          <mesh filename="package://lbr_iiwa_description/meshes/link_1.stl"/>
        </geometry>
        <material name="Orange"/>
      </collision>
    </link>

    <!--  <transmission name="${name}_arm_0_trans" type="pr2_mechanism_model/SimpleTransmission">
	 <actuator name="${name}_arm_0_motor"/>
	 <joint name="${name}_arm_0_joint"/>
	 <mechanicalReduction>1.0</mechanicalReduction>
	 </transmission> -->

    <!-- joint between link_1 and link_2 -->
    <joint name="${name}_joint_2" type="revolute">
      <parent link="${name}_link_1"/>
      <child link="${name}_link_2"/>
      <origin xyz="0 0 0.20" rpy="0 0 0"/>
      <axis xyz="0 0 1"/>
      <limit lower="${-120 * PI / 180}" upper="${120 * PI / 180}"
             effort="306" velocity="${velocity_scale_factor * 110 * PI / 180}" />  
      <!-- <safety_controller soft_lower_limit="${-118 * PI / 180}"
           soft_upper_limit="${118 * PI / 180}"
           k_position="${safety_controller_k_pos}"
           k_velocity="${safety_controller_k_vel}"/> -->
      <dynamics damping="${joint_damping}"/>
    </joint>

    <link name="${name}_link_2">
      <inertial>
        <origin xyz="0 0.06 0.04" rpy="0 0 0"/>
        <mass value="4"/>
        <inertia ixx="0.05"  ixy="0"  ixz="0" iyy="0.02" iyz="0" izz="0.04" />
      </inertial>

      <visual>
        <origin xyz="0 0 0" rpy="0 0 0"/>
        <geometry>
          <mesh filename="package://lbr_iiwa_description/meshes/link_2.stl"/>
        </geometry>
        <material name="Orange"/>
      </visual>

      <collision>
        <origin xyz="0 0 0" rpy="0 0 0"/>
        <geometry>
          <mesh filename="package://lbr_iiwa_description/meshes/link_2.stl"/>
        </geometry>
        <material name="Orange"/>
      </collision>
    </link>

    <!--  <transmission name="${name}_arm_1_trans" type="pr2_mechanism_model/SimpleTransmission">
	 <actuator name="${name}_arm_1_motor"/>
	 <joint name="${name}_arm_1_joint"/>
	 <mechanicalReduction>1.0</mechanicalReduction>
	 </transmission> -->






    <!--Extensions -->
    <xacro:lbr_iiwa_gazebo name="${name}" />

  </xacro:macro>

</robot>
